{
 "cells": [
  {
   "cell_type": "code",
   "execution_count": 7,
   "id": "c08f6418",
   "metadata": {},
   "outputs": [],
   "source": [
    "# Importa las bibliotecas necesarias\n",
    "import tensorflow as tf\n",
    "from tensorflow import keras\n",
    "import numpy as np\n",
    "from keras.datasets import cifar10"
   ]
  },
  {
   "cell_type": "code",
   "execution_count": 8,
   "id": "1fd73196",
   "metadata": {},
   "outputs": [],
   "source": [
    "# Loading in the data\n",
    "(X_train, y_train), (X_test, y_test) = cifar10.load_data()"
   ]
  },
  {
   "cell_type": "code",
   "execution_count": 10,
   "id": "a31a819d",
   "metadata": {},
   "outputs": [],
   "source": [
    "# Preprocesa los datos de la imagen\n",
    "X_train = X_train / 255.0\n",
    "X_test = X_test / 255.0"
   ]
  },
  {
   "cell_type": "code",
   "execution_count": 11,
   "id": "f1fc04cc",
   "metadata": {},
   "outputs": [
    {
     "name": "stderr",
     "output_type": "stream",
     "text": [
      "2023-04-26 14:49:56.232501: I tensorflow/compiler/xla/stream_executor/cuda/cuda_gpu_executor.cc:981] successful NUMA node read from SysFS had negative value (-1), but there must be at least one NUMA node, so returning NUMA node zero\n",
      "2023-04-26 14:49:56.245896: W tensorflow/compiler/xla/stream_executor/platform/default/dso_loader.cc:64] Could not load dynamic library 'libcudnn.so.8'; dlerror: libcudnn.so.8: cannot open shared object file: No such file or directory\n",
      "2023-04-26 14:49:56.245920: W tensorflow/core/common_runtime/gpu/gpu_device.cc:1934] Cannot dlopen some GPU libraries. Please make sure the missing libraries mentioned above are installed properly if you would like to use GPU. Follow the guide at https://www.tensorflow.org/install/gpu for how to download and setup the required libraries for your platform.\n",
      "Skipping registering GPU devices...\n",
      "2023-04-26 14:49:56.246371: I tensorflow/core/platform/cpu_feature_guard.cc:193] This TensorFlow binary is optimized with oneAPI Deep Neural Network Library (oneDNN) to use the following CPU instructions in performance-critical operations:  AVX2 AVX512F AVX512_VNNI FMA\n",
      "To enable them in other operations, rebuild TensorFlow with the appropriate compiler flags.\n"
     ]
    }
   ],
   "source": [
    "# Define el modelo de aprendizaje profundo\n",
    "model = keras.Sequential([\n",
    "    keras.layers.Conv2D(32, (3, 3), activation='relu', input_shape=(64, 64, 3)),\n",
    "    keras.layers.MaxPooling2D((2, 2)),\n",
    "    keras.layers.Conv2D(64, (3, 3), activation='relu'),\n",
    "    keras.layers.MaxPooling2D((2, 2)),\n",
    "    keras.layers.Flatten(),\n",
    "    keras.layers.Dense(128, activation='relu'),\n",
    "    keras.layers.Dense(1, activation='sigmoid')\n",
    "])"
   ]
  },
  {
   "cell_type": "code",
   "execution_count": 12,
   "id": "b114f4c7",
   "metadata": {},
   "outputs": [],
   "source": [
    "# Compila el modelo\n",
    "model.compile(optimizer='adam',\n",
    "              loss='binary_crossentropy',\n",
    "              metrics=['accuracy'])"
   ]
  },
  {
   "cell_type": "code",
   "execution_count": 15,
   "id": "d8f64d7e",
   "metadata": {},
   "outputs": [
    {
     "name": "stdout",
     "output_type": "stream",
     "text": [
      "Epoch 1/10\n"
     ]
    },
    {
     "ename": "ValueError",
     "evalue": "in user code:\n\n    File \"/home/luisangel/luis-env/lib/python3.9/site-packages/keras/engine/training.py\", line 1249, in train_function  *\n        return step_function(self, iterator)\n    File \"/home/luisangel/luis-env/lib/python3.9/site-packages/keras/engine/training.py\", line 1233, in step_function  **\n        outputs = model.distribute_strategy.run(run_step, args=(data,))\n    File \"/home/luisangel/luis-env/lib/python3.9/site-packages/keras/engine/training.py\", line 1222, in run_step  **\n        outputs = model.train_step(data)\n    File \"/home/luisangel/luis-env/lib/python3.9/site-packages/keras/engine/training.py\", line 1023, in train_step\n        y_pred = self(x, training=True)\n    File \"/home/luisangel/luis-env/lib/python3.9/site-packages/keras/utils/traceback_utils.py\", line 70, in error_handler\n        raise e.with_traceback(filtered_tb) from None\n    File \"/home/luisangel/luis-env/lib/python3.9/site-packages/keras/engine/input_spec.py\", line 295, in assert_input_compatibility\n        raise ValueError(\n\n    ValueError: Input 0 of layer \"sequential\" is incompatible with the layer: expected shape=(None, 64, 64, 3), found shape=(None, 32, 32, 3)\n",
     "output_type": "error",
     "traceback": [
      "\u001b[0;31m---------------------------------------------------------------------------\u001b[0m",
      "\u001b[0;31mValueError\u001b[0m                                Traceback (most recent call last)",
      "Cell \u001b[0;32mIn [15], line 2\u001b[0m\n\u001b[1;32m      1\u001b[0m \u001b[38;5;66;03m# Entrena el modelo\u001b[39;00m\n\u001b[0;32m----> 2\u001b[0m \u001b[43mmodel\u001b[49m\u001b[38;5;241;43m.\u001b[39;49m\u001b[43mfit\u001b[49m\u001b[43m(\u001b[49m\u001b[43mX_train\u001b[49m\u001b[43m,\u001b[49m\u001b[43m \u001b[49m\u001b[43my_train\u001b[49m\u001b[43m,\u001b[49m\u001b[43m \u001b[49m\u001b[43mepochs\u001b[49m\u001b[38;5;241;43m=\u001b[39;49m\u001b[38;5;241;43m10\u001b[39;49m\u001b[43m,\u001b[49m\u001b[43m \u001b[49m\u001b[43mbatch_size\u001b[49m\u001b[38;5;241;43m=\u001b[39;49m\u001b[38;5;241;43m32\u001b[39;49m\u001b[43m)\u001b[49m\n",
      "File \u001b[0;32m~/luis-env/lib/python3.9/site-packages/keras/utils/traceback_utils.py:70\u001b[0m, in \u001b[0;36mfilter_traceback.<locals>.error_handler\u001b[0;34m(*args, **kwargs)\u001b[0m\n\u001b[1;32m     67\u001b[0m     filtered_tb \u001b[38;5;241m=\u001b[39m _process_traceback_frames(e\u001b[38;5;241m.\u001b[39m__traceback__)\n\u001b[1;32m     68\u001b[0m     \u001b[38;5;66;03m# To get the full stack trace, call:\u001b[39;00m\n\u001b[1;32m     69\u001b[0m     \u001b[38;5;66;03m# `tf.debugging.disable_traceback_filtering()`\u001b[39;00m\n\u001b[0;32m---> 70\u001b[0m     \u001b[38;5;28;01mraise\u001b[39;00m e\u001b[38;5;241m.\u001b[39mwith_traceback(filtered_tb) \u001b[38;5;28;01mfrom\u001b[39;00m \u001b[38;5;28mNone\u001b[39m\n\u001b[1;32m     71\u001b[0m \u001b[38;5;28;01mfinally\u001b[39;00m:\n\u001b[1;32m     72\u001b[0m     \u001b[38;5;28;01mdel\u001b[39;00m filtered_tb\n",
      "File \u001b[0;32m/tmp/__autograph_generated_fileb99jxl_f.py:15\u001b[0m, in \u001b[0;36mouter_factory.<locals>.inner_factory.<locals>.tf__train_function\u001b[0;34m(iterator)\u001b[0m\n\u001b[1;32m     13\u001b[0m \u001b[38;5;28;01mtry\u001b[39;00m:\n\u001b[1;32m     14\u001b[0m     do_return \u001b[38;5;241m=\u001b[39m \u001b[38;5;28;01mTrue\u001b[39;00m\n\u001b[0;32m---> 15\u001b[0m     retval_ \u001b[38;5;241m=\u001b[39m ag__\u001b[38;5;241m.\u001b[39mconverted_call(ag__\u001b[38;5;241m.\u001b[39mld(step_function), (ag__\u001b[38;5;241m.\u001b[39mld(\u001b[38;5;28mself\u001b[39m), ag__\u001b[38;5;241m.\u001b[39mld(iterator)), \u001b[38;5;28;01mNone\u001b[39;00m, fscope)\n\u001b[1;32m     16\u001b[0m \u001b[38;5;28;01mexcept\u001b[39;00m:\n\u001b[1;32m     17\u001b[0m     do_return \u001b[38;5;241m=\u001b[39m \u001b[38;5;28;01mFalse\u001b[39;00m\n",
      "\u001b[0;31mValueError\u001b[0m: in user code:\n\n    File \"/home/luisangel/luis-env/lib/python3.9/site-packages/keras/engine/training.py\", line 1249, in train_function  *\n        return step_function(self, iterator)\n    File \"/home/luisangel/luis-env/lib/python3.9/site-packages/keras/engine/training.py\", line 1233, in step_function  **\n        outputs = model.distribute_strategy.run(run_step, args=(data,))\n    File \"/home/luisangel/luis-env/lib/python3.9/site-packages/keras/engine/training.py\", line 1222, in run_step  **\n        outputs = model.train_step(data)\n    File \"/home/luisangel/luis-env/lib/python3.9/site-packages/keras/engine/training.py\", line 1023, in train_step\n        y_pred = self(x, training=True)\n    File \"/home/luisangel/luis-env/lib/python3.9/site-packages/keras/utils/traceback_utils.py\", line 70, in error_handler\n        raise e.with_traceback(filtered_tb) from None\n    File \"/home/luisangel/luis-env/lib/python3.9/site-packages/keras/engine/input_spec.py\", line 295, in assert_input_compatibility\n        raise ValueError(\n\n    ValueError: Input 0 of layer \"sequential\" is incompatible with the layer: expected shape=(None, 64, 64, 3), found shape=(None, 32, 32, 3)\n"
     ]
    }
   ],
   "source": [
    "# Entrena el modelo\n",
    "model.fit(X_train, y_train, epochs=10, batch_size=32)"
   ]
  },
  {
   "cell_type": "code",
   "execution_count": null,
   "id": "205eb275",
   "metadata": {},
   "outputs": [],
   "source": []
  }
 ],
 "metadata": {
  "kernelspec": {
   "display_name": "Python 3 (ipykernel)",
   "language": "python",
   "name": "python3"
  },
  "language_info": {
   "codemirror_mode": {
    "name": "ipython",
    "version": 3
   },
   "file_extension": ".py",
   "mimetype": "text/x-python",
   "name": "python",
   "nbconvert_exporter": "python",
   "pygments_lexer": "ipython3",
   "version": "3.9.7"
  }
 },
 "nbformat": 4,
 "nbformat_minor": 5
}
